<robot name="simple_robot" xmlns:xacro="http://www.ros.org/wiki/xacro">
  <link name="base_link"> <!-- Each link should have a name to distinguish and refer to them -->
    <visual>
      <origin xyz="0 0 0" rpy="0 0 0"/>
      <geometry>
        <box size="0.2 0.2 0.2"/> <!-- This specifies the shape of the link -->
      </geometry>
      <material name="base_material">
        <color rgba="0.5 0.5 0.5 1"/> <!-- This specifies the color of the link -->
      </material>
    </visual>
  </link>

  <link name="link_1">
    <visual>
      <origin xyz="0 0 0.3" rpy="0 0 0"/>
      <geometry>
        <cylinder length="0.6" radius="0.1"/> 
      </geometry>
      <material name="link1_material">
        <color rgba="0 1 0 1"/>
      </material>
    </visual>
  </link>

  <joint name="base_to_link_1" type="continuous">
    <!-- <origin xyz="0 0 0.2" rpy="${pi/2} 0 0"/>
    <axis xyz="0 1 0"/> -->
    <parent link="base_link"/>
    <child link="link_1"/>
  </joint>
</robot>
